[2024-09-02T16:12:17.937+0000] {local_task_job_runner.py:123} INFO - ::group::Pre task execution logs
[2024-09-02T16:12:17.953+0000] {taskinstance.py:2603} INFO - Dependencies all met for dep_context=non-requeueable deps ti=<TaskInstance: our_first_dag_v2.second_task manual__2024-09-02T16:10:15.213973+00:00 [queued]>
[2024-09-02T16:12:17.972+0000] {taskinstance.py:2603} INFO - Dependencies all met for dep_context=requeueable deps ti=<TaskInstance: our_first_dag_v2.second_task manual__2024-09-02T16:10:15.213973+00:00 [queued]>
[2024-09-02T16:12:17.974+0000] {taskinstance.py:2856} INFO - Starting attempt 2 of 6
[2024-09-02T16:12:17.988+0000] {taskinstance.py:2879} INFO - Executing <Task(BashOperator): second_task> on 2024-09-02 16:10:15.213973+00:00
[2024-09-02T16:12:18.003+0000] {logging_mixin.py:190} WARNING - /home/***/.local/lib/python3.12/site-packages/***/task/task_runner/standard_task_runner.py:70 DeprecationWarning: This process (pid=3881) is multi-threaded, use of fork() may lead to deadlocks in the child.
[2024-09-02T16:12:17.999+0000] {standard_task_runner.py:104} INFO - Running: ['***', 'tasks', 'run', 'our_first_dag_v2', 'second_task', 'manual__2024-09-02T16:10:15.213973+00:00', '--job-id', '6', '--raw', '--subdir', 'DAGS_FOLDER/our_first_dag.py', '--cfg-path', '/tmp/tmprehd5lj3']
[2024-09-02T16:12:18.006+0000] {standard_task_runner.py:105} INFO - Job 6: Subtask second_task
[2024-09-02T16:12:18.005+0000] {standard_task_runner.py:72} INFO - Started process 3882 to run task
[2024-09-02T16:12:18.286+0000] {task_command.py:467} INFO - Running <TaskInstance: our_first_dag_v2.second_task manual__2024-09-02T16:10:15.213973+00:00 [running]> on host cedbab6b7256
[2024-09-02T16:12:18.375+0000] {taskinstance.py:3122} INFO - Exporting env vars: AIRFLOW_CTX_DAG_OWNER='abhay' AIRFLOW_CTX_DAG_ID='our_first_dag_v2' AIRFLOW_CTX_TASK_ID='second_task' AIRFLOW_CTX_EXECUTION_DATE='2024-09-02T16:10:15.213973+00:00' AIRFLOW_CTX_TRY_NUMBER='2' AIRFLOW_CTX_DAG_RUN_ID='manual__2024-09-02T16:10:15.213973+00:00'
[2024-09-02T16:12:18.377+0000] {taskinstance.py:731} INFO - ::endgroup::
[2024-09-02T16:12:18.393+0000] {subprocess.py:63} INFO - Tmp dir root location: /tmp
[2024-09-02T16:12:18.395+0000] {subprocess.py:75} INFO - Running command: ['/usr/bin/bash', '-c', 'I am the second task']
[2024-09-02T16:12:18.438+0000] {subprocess.py:86} INFO - Output:
[2024-09-02T16:12:18.446+0000] {subprocess.py:93} INFO - /usr/bin/bash: line 1: I: command not found
[2024-09-02T16:12:18.448+0000] {subprocess.py:97} INFO - Command exited with return code 127
[2024-09-02T16:12:18.463+0000] {taskinstance.py:3301} ERROR - Task failed with exception
Traceback (most recent call last):
  File "/home/airflow/.local/lib/python3.12/site-packages/airflow/models/taskinstance.py", line 767, in _execute_task
    result = _execute_callable(context=context, **execute_callable_kwargs)
             ^^^^^^^^^^^^^^^^^^^^^^^^^^^^^^^^^^^^^^^^^^^^^^^^^^^^^^^^^^^^^
  File "/home/airflow/.local/lib/python3.12/site-packages/airflow/models/taskinstance.py", line 733, in _execute_callable
    return ExecutionCallableRunner(
           ^^^^^^^^^^^^^^^^^^^^^^^^
  File "/home/airflow/.local/lib/python3.12/site-packages/airflow/utils/operator_helpers.py", line 252, in run
    return self.func(*args, **kwargs)
           ^^^^^^^^^^^^^^^^^^^^^^^^^^
  File "/home/airflow/.local/lib/python3.12/site-packages/airflow/models/baseoperator.py", line 406, in wrapper
    return func(self, *args, **kwargs)
           ^^^^^^^^^^^^^^^^^^^^^^^^^^^
  File "/home/airflow/.local/lib/python3.12/site-packages/airflow/operators/bash.py", line 249, in execute
    raise AirflowException(
airflow.exceptions.AirflowException: Bash command failed. The command returned a non-zero exit code 127.
[2024-09-02T16:12:18.471+0000] {taskinstance.py:1225} INFO - Marking task as UP_FOR_RETRY. dag_id=our_first_dag_v2, task_id=second_task, run_id=manual__2024-09-02T16:10:15.213973+00:00, execution_date=20240902T161015, start_date=20240902T161217, end_date=20240902T161218
[2024-09-02T16:12:18.497+0000] {taskinstance.py:340} INFO - ::group::Post task execution logs
[2024-09-02T16:12:18.509+0000] {standard_task_runner.py:124} ERROR - Failed to execute job 6 for task second_task (Bash command failed. The command returned a non-zero exit code 127.; 3882)
Traceback (most recent call last):
  File "/home/airflow/.local/lib/python3.12/site-packages/airflow/task/task_runner/standard_task_runner.py", line 117, in _start_by_fork
    ret = args.func(args, dag=self.dag)
          ^^^^^^^^^^^^^^^^^^^^^^^^^^^^^
  File "/home/airflow/.local/lib/python3.12/site-packages/airflow/cli/cli_config.py", line 49, in command
    return func(*args, **kwargs)
           ^^^^^^^^^^^^^^^^^^^^^
  File "/home/airflow/.local/lib/python3.12/site-packages/airflow/utils/cli.py", line 115, in wrapper
    return f(*args, **kwargs)
           ^^^^^^^^^^^^^^^^^^
  File "/home/airflow/.local/lib/python3.12/site-packages/airflow/cli/commands/task_command.py", line 483, in task_run
    task_return_code = _run_task_by_selected_method(args, _dag, ti)
                       ^^^^^^^^^^^^^^^^^^^^^^^^^^^^^^^^^^^^^^^^^^^^
  File "/home/airflow/.local/lib/python3.12/site-packages/airflow/cli/commands/task_command.py", line 256, in _run_task_by_selected_method
    return _run_raw_task(args, ti)
           ^^^^^^^^^^^^^^^^^^^^^^^
  File "/home/airflow/.local/lib/python3.12/site-packages/airflow/cli/commands/task_command.py", line 341, in _run_raw_task
    return ti._run_raw_task(
           ^^^^^^^^^^^^^^^^^
  File "/home/airflow/.local/lib/python3.12/site-packages/airflow/utils/session.py", line 97, in wrapper
    return func(*args, session=session, **kwargs)
           ^^^^^^^^^^^^^^^^^^^^^^^^^^^^^^^^^^^^^^
  File "/home/airflow/.local/lib/python3.12/site-packages/airflow/models/taskinstance.py", line 2995, in _run_raw_task
    return _run_raw_task(
           ^^^^^^^^^^^^^^
  File "/home/airflow/.local/lib/python3.12/site-packages/airflow/models/taskinstance.py", line 273, in _run_raw_task
    TaskInstance._execute_task_with_callbacks(
  File "/home/airflow/.local/lib/python3.12/site-packages/airflow/models/taskinstance.py", line 3149, in _execute_task_with_callbacks
    result = self._execute_task(context, task_orig)
             ^^^^^^^^^^^^^^^^^^^^^^^^^^^^^^^^^^^^^^
  File "/home/airflow/.local/lib/python3.12/site-packages/airflow/models/taskinstance.py", line 3173, in _execute_task
    return _execute_task(self, context, task_orig)
           ^^^^^^^^^^^^^^^^^^^^^^^^^^^^^^^^^^^^^^^
  File "/home/airflow/.local/lib/python3.12/site-packages/airflow/models/taskinstance.py", line 767, in _execute_task
    result = _execute_callable(context=context, **execute_callable_kwargs)
             ^^^^^^^^^^^^^^^^^^^^^^^^^^^^^^^^^^^^^^^^^^^^^^^^^^^^^^^^^^^^^
  File "/home/airflow/.local/lib/python3.12/site-packages/airflow/models/taskinstance.py", line 733, in _execute_callable
    return ExecutionCallableRunner(
           ^^^^^^^^^^^^^^^^^^^^^^^^
  File "/home/airflow/.local/lib/python3.12/site-packages/airflow/utils/operator_helpers.py", line 252, in run
    return self.func(*args, **kwargs)
           ^^^^^^^^^^^^^^^^^^^^^^^^^^
  File "/home/airflow/.local/lib/python3.12/site-packages/airflow/models/baseoperator.py", line 406, in wrapper
    return func(self, *args, **kwargs)
           ^^^^^^^^^^^^^^^^^^^^^^^^^^^
  File "/home/airflow/.local/lib/python3.12/site-packages/airflow/operators/bash.py", line 249, in execute
    raise AirflowException(
airflow.exceptions.AirflowException: Bash command failed. The command returned a non-zero exit code 127.
[2024-09-02T16:12:18.566+0000] {local_task_job_runner.py:261} INFO - Task exited with return code 1
[2024-09-02T16:12:18.582+0000] {taskinstance.py:3891} INFO - 0 downstream tasks scheduled from follow-on schedule check
[2024-09-02T16:12:18.585+0000] {local_task_job_runner.py:240} INFO - ::endgroup::
